Workbook

Sheet Contents (Indice)
A1: CONTENTS
B19: Nu Holdings Ltd.
B20: Investors Relations | Relações com Investidores
B21: investors@nubank.com.br
B23: CONSOLIDATED FINANCIAL STATEMENTS IN IFRS | J23: MANAGERIAL INFORMATION
D25: Consolidated Statement of Profit or Loss - Quarter | K25: Non-Performing Loans (NPLs)
D26: Consolidated Statement of Profit or Loss - Accumulated | K26: Operating Figures
D27: Consolidated Statement of Financial Position | K27: Managerial Indicators
D28: Consolidated Statement of Cash Flow | K28: Financing
D29: Revenue Breakdown
D30: Expenses Breakdown
D31: Credit Operations
D32: Write-offs and Recoveries
B36: DEMONSTRAÇÕES FINANCEIRAS CONSOLIDADAS EM IFRS | J36: INFORMAÇÕES GERENCIAIS
D38: Demonstrações do Resultado Consolidadas - Trimestre | K38: Inadimplência
D39: Demonstrações do Resultado Consolidadas - Acumulado | K39: Informações Operacionais
D40: Balanços Patrimoniais Consolidados | K40: Indicadores Gerenciais
D41: Demonstrações Consolidadas do Fluxo de Caixa | K41: Empréstimos
D42: Abertura das Receitas
D43: Abertura das Despesas
D44: Operações de Crédito
D45: Baixas e Recuperação das Carteiras

Sheet Profit or loss (Resultado) - qu
B2: Nu Holdings Ltd. | R2: Nu Holdings Ltd.
B3: Consolidated Statement of Profit or Loss - Quarter | R3: Demonstrações do Resultado Consolidadas - Trimestre
B4: Amounts in thousands of US$, except earnings (loss) per share | R4: Valores em R$ mil, exceto o resultado por ação
B5: Back to Contents | R5: Retornar ao Índice
C9: 3-MONTH PERIOD ENDED | S9: PERÍODO DE 3 MESES FINDOS EM
C10: 31/03/2023 | D10: 44926 | E10: 44834 | F10: 44742 | G10: 44651 | H10: 44561 | I10: 44469 | J10: 44377 | K10: 44286 | L10: 44196 | M10: 44104 | N10: 44012 | O10: 43921 | S10: 31/03/2023 | T10: 44926 | U10: 44834 | V10: 44742 | W10: 44651 | X10: 44561 | Y10: 44469 | Z10: 44377 | AA10: 44286 | AB10: 44196 | AC10: 44104 | AD10: 44012 | AE10: 43921
C11: US$ | D11: US$ | E11: US$ | F11: US$ | G11: US$ | H11: US$ | I11: US$ | J11: US$ | K11: US$ | L11: US$ | M11: US$ | N11: US$ | O11: US$ | S11: R$ | T11: R$ | U11: R$ | V11: R$ | W11: R$ | X11: R$ | Y11: R$ | Z11: R$ | AA11: R$ | AB11: R$ | AC11: R$ | AD11: R$ | AE11: R$
B12: Interest income and gains (losses) on financial instruments | C12: 1255454 | D12: ='Profit or loss (Resultado)-accu'!D12-'Profit or loss (Resultado)-accu'!E12 -> 1095509 | E12: 987248 | F12: 853013 | G12: 619443 | H12: 439550 | I12: 294958 | J12: 184893 | K12: 127345 | L12: 89655 | M12: 70140 | N12: 91884 | O12: 131243 | R12: Receita de juros e ganhos (perdas) sobre instrumentos financeiros | S12: 6518819 | T12: ='Profit or loss (Resultado)-accu'!T12-'Profit or loss (Resultado)-accu'!U12 -> 5733900 | U12: 5155508 | V12: 4237744 | W12: 3236590 | X12: ='Profit or loss (Resultado)-accu'!X12-SUM(Y12:AA12) -> 2397359 | Y12: 1556669 | Z12: 995963 | AA12: 698564 | AB12: ='Profit or loss (Resultado)-accu'!AB12-SUM(AC12:AE12) -> 545202 | AC12: 392276 | AD12: 452564 | AE12: 586984
B13: Fee and commission income | C13: 363213 | D13: ='Profit or loss (Resultado)-accu'!D13-'Profit or loss (Resultado)-accu'!E13 -> 355027 | E13: 319619 | F13: 304548 | G13: 257824 | H13: 196415 | I13: 185949 | J13: 151195 | K13: 117718 | L13: 112910 | M13: 85946 | N13: 70443 | O13: 84912 | R13: Receita de tarifas e comissões | S13: 1885947 | T13: ='Profit or loss (Resultado)-accu'!T13-'Profit or loss (Resultado)-accu'!U13 -> 1860810 | U13: 1674102 | V13: 1507527 | W13: 1347130 | X13: ='Profit or loss (Resultado)-accu'!X13-SUM(Y13:AA13) -> 1076747 | Y13: 977543 | Z13: 814442 | AA13: 645754 | AB13: ='Profit or loss (Resultado)-accu'!AB13-SUM(AC13:AE13) -> 640231 | AC13: 461832 | AD13: 346959 | AE13: 379769
B14: Total revenue | C14: 1618667 | D14: =SUM(D12:D13) -> 1450536 | E14: 1306867 | F14: 1157561 | G14: 877267 | H14: 635965 | I14: 480907 | J14: 336088 | K14: 245063 | L14: 202565 | M14: 156086 | N14: 162327 | O14: 216155 | R14: Total das receitas | S14: 8404766 | T14: ='Profit or loss (Resultado)-accu'!T14-'Profit or loss (Resultado)-accu'!U14 -> 7594710 | U14: 6829610 | V14: 5745271 | W14: 4583720 | X14: ='Profit or loss (Resultado)-accu'!X14-SUM(Y14:AA14) -> 3474106 | Y14: 2534212 | Z14: 1810405 | AA14: 1344318 | AB14: ='Profit or loss (Resultado)-accu'!AB14-SUM(AC14:AE14) -> 1185433 | AC14: 854108 | AD14: 799523 | AE14: 966753
B16: Interest and other financial expenses | C16: -440212 | D16: ='Profit or loss (Resultado)-accu'!D16-'Profit or loss (Resultado)-accu'!E16 -> -407511 | E16: -459889 | F16: -407500 | G16: -273003 | H16: -176972 | I16: -101393 | J16: -57236 | K16: -31743 | L16: -31389 | M16: -23984 | N16: -25321 | O16: -33230 | R16: Juros e outras despesas financeiras | S16: -2285757 | T16: ='Profit or loss (Resultado)-accu'!T16-'Profit or loss (Resultado)-accu'!U16 -> -2139812 | U16: -2401270 | V16: -2027860 | W16: -1426441 | X16: ='Profit or loss (Resultado)-accu'!X16-SUM(Y16:AA16) -> -963772 | Y16: -536084 | Z16: -308313 | AA16: -174129 | AB16: ='Profit or loss (Resultado)-accu'!AB16-SUM(AC16:AE16) -> -183549 | AC16: -131304 | AD16: -124716 | AE16: -148621
B17: Transactional expenses | C17: -52778 | D17: ='Profit or loss (Resultado)-accu'!D17-'Profit or loss (Resultado)-accu'!E17 -> -49468 | E17: -44475 | F17: -48036 | G17: -34448 | H17: -32428 | I17: -28560 | J17: -29782 | K17: -26349 | L17: -39165 | M17: -31910 | N17: -22604 | O17: -33136 | R17: Despesas com transações | S17: -274044 | T17: ='Profit or loss (Resultado)-accu'!T17-'Profit or loss (Resultado)-accu'!U17 -> -259402 | U17: -233199 | V17: -238706 | W17: -179991 | X17: ='Profit or loss (Resultado)-accu'!X17-SUM(Y17:AA17) -> -177687 | Y17: -149355 | Z17: -160427 | AA17: -144540 | AB17: ='Profit or loss (Resultado)-accu'!AB17-SUM(AC17:AE17) -> -224052 | AC17: -171159 | AD17: -111334 | AE17: -148201
B18: Credit loss allowance expenses | C18: -474795 | D18: ='Profit or loss (Resultado)-accu'!D18-'Profit or loss (Resultado)-accu'!E18 -> -415223 | E18: -375474 | F18: -338492 | G18: -275722 | H18: -199676 | I18: -127005 | J18: -82668 | K18: -71294 | L18: -55702 | M18: -32939 | N18: -19019 | O18: -61825 | R18: Despesas com provisão para perdas de crédito | S18: -2465326 | T18: ='Profit or loss (Resultado)-accu'!T18-'Profit or loss (Resultado)-accu'!U18 -> -2175036 | U18: -1963939 | V18: -1677165 | W18: -1440647 | X18: ='Profit or loss (Resultado)-accu'!X18-SUM(Y18:AA18) -> -1088049 | Y18: -669247 | Z18: -445308 | AA18: -391090 | AB18: ='Profit or loss (Resultado)-accu'!AB18-SUM(AC18:AE18) -> -324464 | AC18: -180399 | AD18: -93676 | AE18: -276512
B19: Total cost of financial and transactional services provided | C19: -967785 | D19: =SUM(D16:D18) -> -872202 | E19: -879838 | F19: -794028 | G19: -583173 | H19: -409076 | I19: -256958 | J19: -169686 | K19: -129386 | L19: -126256 | M19: -88833 | N19: -66944 | O19: -128191 | R19: Custo total dos serviços financeiros e transacionais prestados | S19: -5025127 | T19: ='Profit or loss (Resultado)-accu'!T19-'Profit or loss (Resultado)-accu'!U19 -> -4574250 | U19: -4598408 | V19: -3943731 | W19: -3047079 | X19: ='Profit or loss (Resultado)-accu'!X19-SUM(Y19:AA19) -> -2229508 | Y19: -1354686 | Z19: -914048 | AA19: -709759 | AB19: ='Profit or loss (Resultado)-accu'!AB19-SUM(AC19:AE19) -> -732065 | AC19: -482862 | AD19: -329726 | AE19: -573334
B21: Gross profit | C21: 650882 | D21: =SUM(D19,D14) -> 578334 | E21: 427029 | F21: 363533 | G21: 294094 | H21: 226889 | I21: 223949 | J21: 166402 | K21: 115677 | L21: 76309 | M21: 67253 | N21: 95383 | O21: 87964 | R21: Lucro bruto | S21: 3379639 | T21: ='Profit or loss (Resultado)-accu'!T21-'Profit or loss (Resultado)-accu'!U21 -> 3020460 | U21: 2231202 | V21: 1801540 | W21: 1536641 | X21: ='Profit or loss (Resultado)-accu'!X21-SUM(Y21:AA21) -> 1244598 | Y21: 1179526 | Z21: 896357 | AA21: 634559 | AB21: ='Profit or loss (Resultado)-accu'!AB21-SUM(AC21:AE21) -> 453368 | AC21: 371246 | AD21: 469797 | AE21: 393419
B23: Operating expenses | R23: Despesas operacionais
B24: Customer support and operations | C24: -107815 | D24: ='Profit or loss (Resultado)-accu'!D24-'Profit or loss (Resultado)-accu'!E24 -> -105840 | E24: -90249 | F24: -77703 | G24: -61571 | H24: -65762 | I24: -51649 | J24: -40968 | K24: -32130 | L24: -28494 | M24: -28930 | N24: -26427 | O24: -40099 | R24: Suporte e operações ao cliente | S24: -559819 | T24: ='Profit or loss (Resultado)-accu'!T24-'Profit or loss (Resultado)-accu'!U24 -> -553719 | U24: -471563 | V24: -385261 | W24: -321708 | X24: ='Profit or loss (Resultado)-accu'!X24-SUM(Y24:AA24) -> -359504 | Y24: -271606 | Z24: -220682 | AA24: -176252 | AB24: ='Profit or loss (Resultado)-accu'!AB24-SUM(AC24:AE24) -> -172720 | AC24: -157728 | AD24: -130163 | AE24: -179343
B25: General and administrative expenses (G&A) | C25: -236881 | D25: ='Profit or loss (Resultado)-accu'!D25-'Profit or loss (Resultado)-accu'!E25 -> -596876 | E25: =SUM(E26:E27) -> -261778 | F25: =SUM(F26:F27) -> -229505 | G25: =SUM(G26:G27) -> -245108 | H25: =SUM(H26:H27) -> -224231 | I25: =SUM(I26:I27) -> -166527 | J25: =SUM(J26:J27) -> -122295 | K25: =SUM(K26:K27) -> -115848 | L25: =SUM(L26:L27) -> -81633 | ... O25: =SUM(O26:O27) -> -70624 | R25: Despesas gerais e administrativas (G&A) | S25: -1229981 | T25: ='Profit or loss (Resultado)-accu'!T25-'Profit or loss (Resultado)-accu'!U25 -> -3105577 | U25: =SUM(U26:U27) -> -1371964 | V25: =SUM(V26:V27) -> -1128494 | W25: =SUM(W26:W27) -> -1280689 | X25: ='Profit or loss (Resultado)-accu'!X25-SUM(Y25:AA25) -> -1223893 | Y25: =SUM(Y26:Y27) -> -875583 | Z25: =SUM(Z26:Z27) -> -658766 | AA25: =SUM(AA26:AA27) -> -635496 | AB25: ='Profit or loss (Resultado)-accu'!AB25-SUM(AC25:AE25) -> -467838 | AC25: =SUM(AC26:AC27) -> -309134 | AD25: =SUM(AD26:AD27) -> -280644 | AE25: =SUM(AE26:AE27) -> -315866
B26: G&A - Contingent share award (CSA) termination | C26: - | D26: ='Profit or loss (Resultado)-accu'!D26-'Profit or loss (Resultado)-accu'!E26 -> -355573 | E26: 0 | F26: 0 | G26: 0 | H26: 0 | I26: 0 | J26: 0 | K26: 0 | L26: 0 | M26: 0 | N26: 0 | O26: 0 | R26: G&A - Rescisão do plano de opções de ações contingentes (CSA) | S26: - | T26: ='Profit or loss (Resultado)-accu'!T26-'Profit or loss (Resultado)-accu'!U26 -> -1836641 | U26: 0 | V26: 0 | W26: 0 | X26: ='Profit or loss (Resultado)-accu'!X26-SUM(Y26:AA26) -> 0 | Y26: 0 | Z26: 0 | AA26: 0 | AB26: ='Profit or loss (Resultado)-accu'!AB26-SUM(AC26:AE26) -> 0 | AC26: 0 | AD26: 0 | AE26: 0
B27: G&A - Other | C27: -236881 | D27: ='Profit or loss (Resultado)-accu'!D27-'Profit or loss (Resultado)-accu'!E27 -> -241303 | E27: -261778 | F27: -229505 | G27: -245108 | H27: -224231 | I27: -166527 | J27: -122295 | K27: -115848 | L27: -81633 | M27: -56788 | N27: -56979 | O27: -70624 | R27: G&A - Outras | S27: -1229981 | T27: ='Profit or loss (Resultado)-accu'!T27-'Profit or loss (Resultado)-accu'!U27 -> -1268936 | U27: -1371964 | V27: -1128494 | W27: -1280689 | X27: ='Profit or loss (Resultado)-accu'!X27-SUM(Y27:AA27) -> -1223893 | Y27: -875583 | Z27: -658766 | AA27: -635496 | AB27: ='Profit or loss (Resultado)-accu'!AB27-SUM(AC27:AE27) -> -467838 | AC27: -309134 | AD27: -280644 | AE27: -315866
B28: Marketing expenses | C28: -19272 | D28: ='Profit or loss (Resultado)-accu'!D28-'Profit or loss (Resultado)-accu'!E28 -> -51078 | E28: -38103 | F28: -36208 | G28: -27608 | H28: -34508 | I28: -25568 | J28: -14631 | K28: -4867 | L28: -7900 | M28: -4088 | N28: -1345 | O28: -6093 | R28: Despesa de marketing | S28: -100068 | T28: ='Profit or loss (Resultado)-accu'!T28-'Profit or loss (Resultado)-accu'!U28 -> -266952 | U28: -199387 | V28: -179684 | W28: -144252 | X28: ='Profit or loss (Resultado)-accu'!X28-SUM(Y28:AA28) -> -188555 | Y28: -135339 | Z28: -78813 | AA28: -26698 | AB28: ='Profit or loss (Resultado)-accu'!AB28-SUM(AC28:AE28) -> -44445 | AC28: -21975 | AD28: -6625 | AE28: -27251
B29: Other income (expenses) | C29: -43285 | D29: ='Profit or loss (Resultado)-accu'!D29-'Profit or loss (Resultado)-accu'!E29 -> -46285 | E29: -31792 | F29: -44729 | G29: -27458 | H29: 9110 | I29: -1962 | J29: 4954 | K29: -16199 | L29: 15911 | M29: -2106 | N29: -5692 | O29: -17648 | R29: Outras receitas (despesas) | S29: -224753 | T29: ='Profit or loss (Resultado)-accu'!T29-'Profit or loss (Resultado)-accu'!U29 -> -242258 | U29: -167473 | V29: -222960 | W29: -143468 | X29: ='Profit or loss (Resultado)-accu'!X29-SUM(Y29:AA29) -> 49935 | Y29: -9869 | Z29: 26686 | AA29: -88861 | AB29: ='Profit or loss (Resultado)-accu'!AB29-SUM(AC29:AE29) -> 72172 | AC29: -14435 | AD29: -28035 | AE29: -78931
B30: Total operating expenses | C30: -407253 | D30: =SUM(D24:D25,D28:D29) -> -800079 | E30: -421922 | F30: -388145 | G30: -361745 | H30: -315391 | I30: -245706 | J30: -172940 | K30: -169044 | L30: -102116 | M30: -91912 | N30: -90443 | O30: -134464 | R30: Total das despesas operacionais | S30: -2114621 | T30: ='Profit or loss (Resultado)-accu'!T30-'Profit or loss (Resultado)-accu'!U30 -> -4168506 | U30: -2210387 | V30: -1916399 | W30: -1890117 | X30: ='Profit or loss (Resultado)-accu'!X30-SUM(Y30:AA30) -> -1722017 | Y30: -1292397 | Z30: -931575 | AA30: -927307 | AB30: ='Profit or loss (Resultado)-accu'!AB30-SUM(AC30:AE30) -> -612831 | AC30: -503272 | AD30: -445467 | AE30: -601391
B32: Results with convertible instruments | C32: - | D32: 0 | E32: 0 | F32: 0 | G32: 0 | H32: 0 | I32: 0 | J32: 0 | K32: 0 | L32: -87965 | M32: -13187 | N32: 0 | O32: 0 | R32: Custos financeiros - resultados com instrumentos conversíveis | S32: - | U32: 0 | V32: 0 | W32: 0 | X32: ='Profit or loss (Resultado)-accu'!X32-SUM(Y32:AA32) -> 0 | Y32: 0 | Z32: 0 | AA32: 0 | AB32: ='Profit or loss (Resultado)-accu'!AB32-SUM(AC32:AE32) -> -455191 | AC32: -67056 | AD32: 0 | AE32: 0
B34: Profit or loss before income taxes | C34: 243629 | D34: =SUM(D30,D21) -> -221745 | E34: 5107 | F34: -24612 | G34: -67651 | H34: -88502 | I34: -21757 | J34: -6538 | K34: -53367 | L34: -113772 | M34: -37846 | N34: 4940 | O34: -46500 | R34: Resultado antes dos tributos | S34: 1265018 | T34: ='Profit or loss (Resultado)-accu'!T34-'Profit or loss (Resultado)-accu'!U34 -> -1148046 | U34: 20815 | V34: -114859 | W34: -353476 | X34: ='Profit or loss (Resultado)-accu'!X34-SUM(Y34:AA34) -> -477419 | Y34: -112871 | Z34: -35218 | AA34: -292748 | AB34: ='Profit or loss (Resultado)-accu'!AB34-SUM(AC34:AE34) -> -614654 | AC34: -199082 | AD34: 24330 | AE34: -207972
B36: Income taxes | R36: Resultado com tributos
B37: Current taxes | C37: -205864 | D37: ='Profit or loss (Resultado)-accu'!D37-'Profit or loss (Resultado)-accu'!E37 -> -171225 | E37: -106819 | F37: -96249 | G37: -99052 | H37: -69694 | I37: -66374 | J37: -52248 | K37: -31508 | L37: -13231 | M37: -182 | N37: -2588 | O37: -6337 | R37: Tributos correntes | S37: -1068928 | T37: ='Profit or loss (Resultado)-accu'!T37-'Profit or loss (Resultado)-accu'!U37 -> -893673 | U37: -559929 | V37: -473820 | W37: -517547 | X37: ='Profit or loss (Resultado)-accu'!X37-SUM(Y37:AA37) -> -382372 | Y37: -349580 | Z37: -281444 | AA37: -172840 | AB37: ='Profit or loss (Resultado)-accu'!AB37-SUM(AC37:AE37) -> -71892 | AC37: -2350 | AD37: -12747 | AE37: -28342
B38: Deferred taxes | C38: 103986 | D38: ='Profit or loss (Resultado)-accu'!D38-'Profit or loss (Resultado)-accu'!E38 -> 95357 | E38: 109545 | F38: 91011 | G38: 121699 | H38: 91922 | I38: 53774 | J38: 43566 | K38: 35392 | L38: 19946 | M38: 5466 | N38: -791 | O38: 19404 | R38: Tributos diferidos | S38: 539937 | T38: ='Profit or loss (Resultado)-accu'!T38-'Profit or loss (Resultado)-accu'!U38 -> 502408 | U38: 574946 | V38: 443860 | W38: 635877 | X38: ='Profit or loss (Resultado)-accu'!X38-SUM(Y38:AA38) -> 500847 | Y38: 282630 | Z38: 234677 | AA38: 194146 | AB38: ='Profit or loss (Resultado)-accu'!AB38-SUM(AC38:AE38) -> 113647 | AC38: 30766 | AD38: -3896 | AE38: 86784
B39: Total income taxes | C39: -101878 | D39: =SUM(D37:D38) -> -75868 | E39: 2726 | F39: -5238 | G39: 22647 | H39: 22228 | I39: -12600 | J39: -8682 | K39: 3884 | L39: 6715 | M39: 5284 | N39: -3379 | O39: 13067 | R39: Total do resultado com tributos | S39: -528991 | T39: ='Profit or loss (Resultado)-accu'!T39-'Profit or loss (Resultado)-accu'!U39 -> -391265 | U39: 15017 | V39: -29960 | W39: 118330 | X39: ='Profit or loss (Resultado)-accu'!X39-SUM(Y39:AA39) -> 118475 | Y39: -66950 | Z39: -46767 | AA39: 21306 | AB39: ='Profit or loss (Resultado)-accu'!AB39-SUM(AC39:AE39) -> 41755 | AC39: 28416 | AD39: -16643 | AE39: 58442
B41: Profit (Loss) for the period/year | C41: 141751 | D41: =SUM(D39,D34) -> -297613 | E41: 7833 | F41: -29850 | G41: -45004 | H41: -66274 | I41: -34357 | J41: -15220 | K41: -49483 | L41: -107057 | M41: -32562 | N41: 1561 | O41: -33433 | R41: Resultado para o período | S41: 736027 | T41: ='Profit or loss (Resultado)-accu'!T41-'Profit or loss (Resultado)-accu'!U41 -> -1539311 | U41: 35832 | V41: -144819 | W41: -235146 | X41: ='Profit or loss (Resultado)-accu'!X41-SUM(Y41:AA41) -> -358944 | Y41: -179821 | Z41: -81985 | AA41: -271442 | AB41: ='Profit or loss (Resultado)-accu'!AB41-SUM(AC41:AE41) -> -572899 | AC41: -170666 | AD41: 7687 | AE41: -149530
B42: Profit (Loss) attributable to shareholders of the parent company | C42: 141751 | D42: ='Profit or loss (Resultado)-accu'!D42-'Profit or loss (Resultado)-accu'!E42 -> -297613 | E42: 7833 | F42: -29697 | G42: -45101 | H42: -66078 | I42: -34212 | J42: -15220 | K42: -49483 | L42: -107057 | M42: -32562 | N42: 1561 | O42: -33433 | R42: Resultado atribuído aos controladores | S42: 736027 | T42: ='Profit or loss (Resultado)-accu'!T42-'Profit or loss (Resultado)-accu'!U42 -> -1539311 | U42: 35832 | V42: -144028 | W42: -235653 | X42: ='Profit or loss (Resultado)-accu'!X42-SUM(Y42:AA42) -> -357877 | Y42: -179048 | Z42: -81985 | AA42: -271442 | AB42: ='Profit or loss (Resultado)-accu'!AB42-SUM(AC42:AE42) -> -572899 | AC42: -170666 | AD42: 7687 | AE42: -149530
B43: Profit (Loss) attributable to non-controlling interests | C43: - | D43: ='Profit or loss (Resultado)-accu'!D43-'Profit or loss (Resultado)-accu'!E43 -> 0 | E43: 0 | F43: -153 | G43: 97 | H43: -196 | I43: -145 | J43: 0 | K43: 0 | L43: 0 | M43: 0 | N43: 0 | O43: 0 | R43: Resultado atribuído aos não controladores (minoritários) | S43: - | T43: ='Profit or loss (Resultado)-accu'!T43-'Profit or loss (Resultado)-accu'!U43 -> 0 | U43: 0 | V43: -791 | W43: 507 | X43: ='Profit or loss (Resultado)-accu'!X43-SUM(Y43:AA43) -> -1067 | Y43: -773 | Z43: 0 | AA43: 0 | AB43: 0 | AD43: 0 | AE43: 0
B45: Earnings (Loss) per share – Basic | C45: 0.0301 | D45: ='Profit or loss (Resultado)-accu'!D45-'Profit or loss (Resultado)-accu'!E45 -> -0.063654018 | E45: 0.0016723476 | F45: -0.0063905328 | G45: -0.0096774851 | H45: -0.0313 | I45: -0.024 | J45: -0.01114 | K45: -0.0367 | L45: -0.0812 | M45: -0.0247 | N45: 0.00119 | O45: -0.0258 | R45: Resultado por ação - básico | S45: 0.1563 | T45: ='Profit or loss (Resultado)-accu'!T45-'Profit or loss (Resultado)-accu'!U45 -> -0.3102 | U45: 0.0077 | V45: -0.030834696 | W45: -0.050564919 | X45: -0.1732 | Y45: -0.1257 | Z45: -0.05999 | AA45: -0.2015 | AB45: -0.4229 | AC45: -0.1292 | AD45: 0.00586 | AE45: -0.1153
B47: Earnings (Loss) per share – Diluted | C47: 0.0294 | D47: ='Profit or loss (Resultado)-accu'!D47-'Profit or loss (Resultado)-accu'!E47 -> -0.063654018 | E47: 0.0016237458 | F47: -0.0063905328 | G47: -0.0096774851 | H47: -0.0313 | I47: -0.024 | J47: -0.01114 | K47: -0.0367 | L47: -0.0812 | M47: -0.0247 | N47: 0.00037 | O47: -0.0258 | R47: Resultado por ação - diluído | S47: 0.1532 | T47: ='Profit or loss (Resultado)-accu'!T47-'Profit or loss (Resultado)-accu'!U47 -> -0.3102 | U47: 0.0074 | V47: -0.030834696 | W47: -0.050564919 | X47: -0.1732 | Y47: -0.1257 | Z47: -0.05999 | AA47: -0.2015 | AB47: -0.4229 | AC47: -0.1292 | AD47: 0.00184 | AE47: -0.1153
B49: Weighted average number of outstanding shares – Basic (in thousands of shares) | C49: 4709505 | D49: 4676977 | E49: 4683835 | F49: 4670972 | G49: 4660405 | H49: 1602126 | I49: 1423876 | J49: 1366612 | K49: 1347258 | L49: 1315578 | M49: 1320606 | N49: 1312236 | O49: 1296708 | R49: Número médio ponderado de ações em circulação - básica (em milhares de ações) | S49: 4709505 | T49: 4676977 | U49: 4683835 | V49: 4670972 | W49: 4660405 | X49: 1602126 | Y49: 1423876 | Z49: 1366612 | AA49: 1347258 | AB49: 1315578 | AC49: 1320606 | AD49: 1312236 | AE49: 1296708
B51: Weighted average number of outstanding shares – Diluted (in thousands of shares) | C51: 4818200 | D51: 4676977 | E51: 4824031 | F51: 4670972 | G51: 4660405 | H51: 1602126 | I51: 1423876 | J51: 1366612 | K51: 1347258 | L51: 1315578 | M51: 1320606 | N51: 4170423 | O51: 1296708 | R51: Número médio ponderado de ações em circulação - diluída (em milhares de ações) | S51: 4818200 | T51: 4676977 | U51: 4824031 | V51: 4670972 | W51: 4660405 | X51: 1602126 | Y51: 1423876 | Z51: 1366612 | AA51: 1347258 | AB51: 1315578 | AC51: 1320606 | AD51: 4170423 | AE51: 1296708

Sheet Profit or loss (Resultado)-accu
B2: Nu Holdings Ltd. | R2: Nu Holdings Ltd.
B3: Consolidated Statement of Profit or Loss - Accumulated | R3: Demonstrações do Resultado Consolidadas - Acumulado
B4: Amounts in thousands of US$, except earnings (loss) per share | R4: Valores em R$ mil, exceto o resultado por ação
B5: Back to Contents | R5: Retornar ao Índice
C9: ACCUMULATED | S9: ACUMULADO
C10: 31/03/2023 | D10: 31/12/2022 | E10: 44834 | F10: 44742 | G10: 44651 | H10: 44561 | I10: 44469 | J10: 44377 | K10: 44286 | L10: 44196 | M10: 44104 | N10: 44012 | O10: 43921 | S10: 31/03/2023 | T10: 44926 | U10: 44834 | V10: 44742 | W10: 44651 | X10: 44561 | Y10: 44469 | Z10: 44377 | AA10: 44286 | AB10: 44196 | AC10: 44104 | AD10: 44012 | AE10: 43921
C11: US$ | D11: US$ | E11: US$ | F11: US$ | G11: US$ | H11: US$ | I11: US$ | J11: US$ | K11: US$ | L11: US$ | M11: US$ | N11: US$ | O11: US$ | S11: R$ | T11: R$ | U11: R$ | V11: R$ | W11: R$ | X11: R$ | Y11: R$ | Z11: R$ | AA11: R$ | AB11: R$ | AC11: R$ | AD11: R$ | AE11: R$
B12: Interest income and gains (losses) on financial instruments | C12: 1255454 | D12: 3555213 | E12: 2459704 | F12: 1472456 | G12: 619443 | H12: 1046746 | I12: 607196 | J12: 312238 | K12: 127345 | L12: 382922 | M12: 293267 | N12: 223127 | O12: 131243 | R12: Receita de juros e ganhos (perdas) sobre instrumentos financeiros | S12: 6518819 | T12: 18363742 | U12: 12629842 | V12: 7474334 | W12: 3236590 | X12: 5648555 | Y12: 3238601 | Z12: 1681932 | AA12: 698564 | AB12: 1977026 | AC12: 1491263 | AD12: 1098987 | AE12: 586984
B13: Fee and commission income | C13: 363213 | D13: 1237018 | E13: 881991 | F13: 562372 | G13: 257824 | H13: 651277 | I13: 454862 | J13: 268913 | K13: 117718 | L13: 354211 | M13: 241301 | N13: 155355 | O13: 84912 | R13: Receita de tarifas e comissões | S13: 1885947 | T13: 6389569 | U13: 4528759 | V13: 2854657 | W13: 1347130 | X13: 3514486 | Y13: 2426097 | Z13: 1448554 | AA13: 645754 | AB13: 1828791 | AC13: 1227016 | AD13: 765184 | AE13: 379769
B14: Total revenue | C14: 1618667 | D14: =SUM(D12:D13) -> 4792231 | E14: 3341695 | F14: 2034828 | G14: 877267 | H14: =SUM(H12:H13) -> 1698023 | I14: 1062058 | J14: 581151 | K14: 245063 | L14: 737133 | M14: 534568 | N14: 378482 | O14: 216155 | R14: Total das receitas | S14: 8404766 | T14: 24753311 | U14: 17158601 | V14: 10328991 | W14: 4583720 | X14: 9163041 | Y14: 5664698 | Z14: 3130486 | AA14: 1344318 | AB14: 3805817 | AC14: 2718279 | AD14: 1864171 | AE14: 966753
B16: Interest and other financial expenses | C16: -440212 | D16: -1547903 | E16: -1140392 | F16: -680503 | G16: -273003 | H16: -367344 | I16: -190372 | J16: -88979 | K16: -31743 | L16: -113924 | M16: -82535 | N16: -58551 | O16: -33230 | R16: Juros e outras despesas financeiras | S16: -2285757 | T16: -7995383 | U16: -5855571 | V16: -3454301 | W16: -1426441 | X16: -1982298 | Y16: -1015387 | Z16: -479303 | AA16: -174129 | AB16: -588190 | AC16: -419690 | AD16: -288386 | AE16: -148621
B17: Transactional expenses | C17: -52778 | D17: -176427 | E17: -126959 | F17: -82484 | G17: -34448 | H17: -117119 | I17: -84691 | J17: -56131 | K17: -26349 | L17: -126815 | M17: -87650 | N17: -55740 | O17: -33136 | R17: Despesas com transações | S17: -274044 | T17: -911298 | U17: -651896 | V17: -418697 | W17: -179991 | X17: -632009 | Y17: -451716 | Z17: -302361 | AA17: -144540 | AB17: -654746 | AC17: -445700 | AD17: -274541 | AE17: -148201
B18: Credit loss allowance expenses | C18: -474795 | D18: -1404911 | E18: -989688 | F18: -614214 | G18: -275722 | H18: -480643 | I18: -280967 | J18: -153962 | K18: -71294 | L18: -169485 | M18: -113783 | N18: -80844 | O18: -61825 | R18: Despesas com provisão para perdas de crédito | S18: -2465326 | T18: -7256787 | U18: -5081751 | V18: -3117812 | W18: -1440647 | X18: -2593694 | Y18: -1498594 | Z18: -829347 | AA18: -391090 | AB18: -875051 | AC18: -578587 | AD18: -398188 | AE18: -276512
B19: Total cost of financial and transactional services provided | C19: -967785 | D19: =SUM(D16:D18) -> -3129241 | E19: -2257039 | F19: -1377201 | G19: -583173 | H19: -965106 | I19: -556030 | J19: -299072 | K19: -129386 | L19: -410224 | M19: -283968 | N19: -195135 | O19: -128191 | R19: Custo total dos serviços financeiros e transacionais prestados | S19: -5025127 | T19: -16163468 | U19: -11589218 | V19: -6990810 | W19: -3047079 | X19: -5208001 | Y19: -2965697 | Z19: -1611011 | AA19: -709759 | AB19: -2117987 | AC19: -1443977 | AD19: -961115 | AE19: -573334
B21: Gross profit | C21: 650882 | D21: =SUM(D14,D19) -> 1662990 | E21: 1084656 | F21: 657627 | G21: 294094 | H21: 732917 | I21: 506028 | J21: 282079 | K21: 115677 | L21: 326909 | M21: 250600 | N21: 183347 | O21: 87964 | R21: Lucro bruto | S21: 3379639 | T21: 8589843 | U21: 5569383 | V21: 3338181 | W21: 1536641 | X21: 3955040 | Y21: 2699001 | Z21: 1519475 | AA21: 634559 | AB21: 1687830 | AC21: 1274302 | AD21: 903056 | AE21: 393419
B23: Operating expenses | R23: Despesas operacionais
B24: Customer support and operations | C24: -107815 | D24: -335363 | E24: -229523 | F24: -139274 | G24: -61571 | H24: -190509 | I24: -124747 | J24: -73098 | K24: -32130 | L24: -123950 | M24: -95456 | N24: -66526 | O24: -40099 | R24: Suporte e operações ao cliente | S24: -559819 | T24: -1732251 | U24: -1178532 | V24: -706969 | W24: -321708 | X24: -1028044 | Y24: -665363 | Z24: -393757 | AA24: -176252 | AB24: -639954 | AC24: -485394 | AD24: -327666 | AE24: -179343
B25: General and administrative expenses (G&A) | C25: -236881 | D25: =SUM(D26:D27) -> -1333267 | E25: =SUM(E26:E27) -> -736391 | F25: =SUM(F26:F27) -> -474613 | G25: =SUM(G26:G27) -> -245108 | H25: =SUM(H26:H27) -> -628901 | I25: =SUM(I26:I27) -> -404670 | J25: =SUM(J26:J27) -> -238143 | K25: =SUM(K26:K27) -> -115848 | ... O25: =SUM(O26:O27) -> -70624 | R25: Despesas gerais e administrativas (G&A) | S25: -1229981 | T25: =SUM(T26:T27) -> -6886724 | U25: =SUM(U26:U27) -> -3781147 | V25: =SUM(V26:V27) -> -2409183 | W25: =SUM(W26:W27) -> -1280689 | X25: =SUM(X26:X27) -> -3393738 | Y25: =SUM(Y26:Y27) -> -2158388 | Z25: =SUM(Z26:Z27) -> -1282805 | AA25: =SUM(AA26:AA27) -> -635496 | ... AE25: =SUM(AE26:AE27) -> -315866
B26: G&A - Contingent share award (CSA) termination | C26: - | D26: -355573 | E26: 0 | F26: 0 | G26: 0 | H26: 0 | I26: 0 | J26: 0 | K26: 0 | L26: 0 | M26: 0 | N26: 0 | O26: 0 | R26: G&A - Rescisão do plano de opções de ações contingentes (CSA) | S26: - | T26: -1836641 | U26: 0 | V26: 0 | W26: 0 | X26: 0 | Y26: 0 | Z26: 0 | AA26: 0 | AB26: 0 | AC26: 0 | AD26: 0 | AE26: 0
B27: G&A - Other | C27: -236881 | D27: -977694 | E27: -736391 | F27: -474613 | G27: -245108 | H27: -628901 | I27: -404670 | J27: -238143 | K27: -115848 | L27: -266024 | M27: -184391 | N27: -127603 | O27: -70624 | R27: G&A - Outras | S27: -1229981 | T27: -5050083 | U27: -3781147 | V27: -2409183 | W27: -1280689 | X27: -3393738 | Y27: -2158388 | Z27: -1282805 | AA27: -635496 | AB27: -1373482 | AC27: -937628 | AD27: -628494 | AE27: -315866
B28: Marketing expenses | C28: -19272 | D28: -152997 | E28: -101919 | F28: -63816 | G28: -27608 | H28: -79574 | I28: -45066 | J28: -19498 | K28: -4867 | L28: -19426 | M28: -11526 | N28: -7438 | O28: -6093 | R28: Despesa de marketing | S28: -100068 | T28: -790275 | U28: -523323 | V28: -323936 | W28: -144252 | X28: -429405 | Y28: -240369 | Z28: -105030 | AA28: -26698 | AB28: -100296 | AC28: -58610 | AD28: -36635 | AE28: -27251
B29: Other income (expenses) | C29: -43285 | D29: -150264 | E29: -103979 | F29: -72187 | G29: -27458 | H29: -4097 | I29: -13207 | J29: -11245 | K29: -16199 | L29: -9535 | M29: -25446 | N29: -23340 | O29: -17648 | R29: Outras receitas (despesas) | S29: -224753 | T29: -776159 | U29: -533901 | V29: -366428 | W29: -143468 | X29: -22109 | Y29: -70442 | Z29: -60573 | AA29: -88861 | AB29: -49229 | AC29: -129394 | AD29: -114959 | AE29: -78931
B30: Total operating expenses | C30: -407253 | D30: =SUM(D24:D25,D28:D29) -> -1971891 | E30: =SUM(E24:E25,E28:E29) -> -1171812 | F30: =SUM(F24:F25,F28:F29) -> -749890 | G30: =SUM(G24:G25,G28:G29) -> -361745 | H30: =SUM(H24:H25,H28:H29) -> -903081 | I30: =SUM(I24:I25,I28:I29) -> -587690 | J30: =SUM(J24:J25,J28:J29) -> -341984 | K30: =SUM(K24:K25,K28:K29) -> -169044 | ... O30: =SUM(O24:O25,O28:O29) -> -134464 | R30: Total das despesas operacionais | S30: -2114621 | T30: -10185409 | U30: -6016903 | V30: -3806516 | W30: -1890117 | X30: -4873296 | Y30: -3134562 | Z30: -1842165 | AA30: -927307 | AB30: -2162961 | AC30: -1611026 | AD30: -1107754 | AE30: -601391
B32: Results with convertible instruments | C32: - | D32: 0 | E32: 0 | F32: 0 | G32: 0 | H32: 0 | I32: 0 | J32: 0 | K32: 0 | L32: -101152 | M32: -13187 | N32: 0 | O32: 0 | R32: Custos financeiros - resultados com instrumentos conversíveis | S32: - | T32: 0 | U32: 0 | V32: 0 | W32: 0 | X32: 0 | Y32: 0 | Z32: 0 | AA32: 0 | AB32: -522247 | AC32: -67056 | AD32: 0 | AE32: 0
B34: Profit (loss) before income taxes | C34: 243629 | D34: =SUM(D21,D30) -> -308901 | E34: -87156 | F34: -92263 | G34: -67651 | H34: -170164 | I34: -81662 | J34: -59905 | K34: -53367 | L34: -193178 | M34: -79406 | N34: -41560 | O34: -46500 | R34: Resultado antes dos tributos sobre o lucro | S34: 1265018 | T34: -1595566 | U34: -447520 | V34: -468335 | W34: -353476 | X34: -918256 | Y34: -435561 | Z34: -322690 | AA34: -292748 | AB34: -997378 | AC34: -403780 | AD34: -204698 | AE34: -207972
B36: Income taxes | R36: Tributos sobre o lucro
B37: Current taxes | C37: -205864 | D37: -473345 | E37: -302120 | F37: -195301 | G37: -99052 | H37: -219824 | I37: -150130 | J37: -83756 | K37: -31508 | L37: -22338 | M37: -9107 | N37: -8925 | O37: -6337 | R37: Tributos correntes | S37: -1068928 | T37: -2444969 | U37: -1551296 | V37: -991367 | W37: -517547 | X37: -1186236 | Y37: -800748 | Z37: -451168 | AA37: -172840 | AB37: -115331 | AC37: -46309 | AD37: -43959 | AE37: -28342
B38: Deferred taxes | C38: 103986 | D38: 417612 | E38: 322255 | F38: 212710 | G38: 121699 | H38: 224654 | I38: 132732 | J38: 78958 | K38: 35392 | L38: 44025 | M38: 24079 | N38: 18613 | O38: 19404 | R38: Tributos diferidos | S38: 539937 | T38: 2157091 | U38: 1654683 | V38: 1079737 | W38: 635877 | X38: 1212300 | Y38: 707953 | Z38: 425323 | AA38: 194146 | AB38: 227301 | AC38: 122442 | AD38: 91676 | AE38: 86784
B39: Total income taxes | C39: -101878 | D39: =SUM(D37:D38) -> -55733 | E39: 20135 | F39: 17409 | G39: 22647 | H39: 4830 | I39: -17398 | J39: -4798 | K39: 3884 | L39: 21687 | M39: 14972 | N39: 9688 | O39: 13067 | R39: Total dos tributos sobre o lucro | S39: -528991 | T39: -287878 | U39: 103387 | V39: 88370 | W39: 118330 | X39: 26064 | Y39: -92795 | Z39: -25845 | AA39: 21306 | AB39: 111970 | AC39: 76133 | AD39: 47717 | AE39: 58442
B41: Profit (Loss) for the period/year | C41: 141751 | D41: =SUM(D34,D39) -> -364634 | E41: -67021 | F41: -74854 | G41: -45004 | H41: -165334 | I41: -99060 | J41: -64703 | K41: -49483 | L41: -171491 | M41: -64434 | N41: -31872 | O41: -33433 | R41: Lucro (Prejuízo) do período / exercício | S41: 736027 | T41: -1883444 | U41: -344133 | V41: -379965 | W41: -235146 | X41: -892192 | Y41: -528356 | Z41: -348535 | AA41: -271442 | AB41: -885408 | AC41: -327647 | AD41: -156981 | AE41: -149530
B42: Profit (Loss) attributable to shareholders of the parent company | C42: 141751 | D42: -364578 | E42: -66965 | F42: -74798 | G42: -45101 | H42: -164993 | I42: -98915 | J42: -64703 | K42: -49483 | L42: -171491 | M42: -64434 | N42: -31872 | O42: -33433 | R42: Lucro (Prejuízo) atribuído aos controladores | S42: 736027 | T42: -1883160 | U42: -343849 | V42: -379681 | W42: -235653 | X42: -890352 | Y42: -527583 | Z42: -348535 | AA42: -271442 | AB42: -885408 | AC42: -327647 | AD42: -156981 | AE42: -149530
B43: Profit (Loss) attributable to non-controlling interests | C43: - | D43: -56 | E43: -56 | F43: -56 | G43: 97 | H43: -341 | I43: -145 | J43: 0 | K43: 0 | L43: 0 | M43: 0 | N43: - | O43: 0 | R43: Lucro (Prejuízo) atribuído aos não controladores (minoritários) | S43: - | T43: -284 | U43: -284 | V43: -284 | W43: 507 | X43: -1840 | Y43: -773 | Z43: 0 | AA43: 0 | AB43: 0 | AC43: 0 | AD43: 0 | AE43: 0
B45: Earnings (loss) per share – Basic | C45: 0.0301 | D45: =-0.078 -> -0.078 | E45: -0.014345982 | F45: -0.016031503 | G45: -0.0096774851 | H45: -0.103 | I45: -0.0717 | J45: -0.04768 | K45: -0.0367 | L45: -0.1304 | M45: -0.0492 | N45: -0.2443 | O45: -0.0258 | R45: Resultado por ação - básico | S45: 0.1563 | T45: -0.3838 | U45: -0.0736 | V45: -0.081377273 | W45: -0.050564919 | X45: -0.5557 | Y45: -0.3825 | Z45: -0.25682 | AA45: -0.2015 | AB45: -0.673 | AC45: -0.2501 | AD45: -0.12035 | AE45: -0.1153
B47: Earnings (loss) per share – Diluted | C47: 0.0294 | D47: =-0.078 -> -0.078 | E47: -0.014345982 | F47: -0.016031503 | G47: -0.0096774851 | H47: -0.103 | I47: -0.0717 | J47: -0.04768 | K47: -0.0367 | L47: -0.1304 | M47: -0.0492 | N47: -0.2443 | O47: -0.0258 | R47: Resultado por ação - diluído | S47: 0.1528 | T47: -0.3838 | U47: -0.0736 | V47: -0.081377273 | W47: -0.050564919 | X47: -0.5557 | Y47: -0.3825 | Z47: -0.25682 | AA47: -0.2015 | AB47: -0.673 | AC47: -0.2501 | AD47: -0.12035 | AE47: -0.1153
B49: Weighted average number of outstanding shares – Basic (in thousands of shares) | C49: 4709505 | D49: 4676977 | E49: 4671761 | F49: 4665688.4 | G49: 4660405 | H49: 1602126 | I49: 1379271 | J49: 1357132 | K49: 1347258 | L49: 1315578 | M49: 1309861 | N49: 1304431 | O49: 1296708 | R49: Número médio ponderado de ações em circulação - básica (em milhares de ações) | S49: 4709505 | T49: 4676977 | U49: 4671761 | V49: 4665688.4 | W49: 4660405 | X49: 1602126 | Y49: 1379271 | Z49: 1357132 | AA49: 1347258 | AB49: 1315578 | AC49: 1309861 | AD49: 1304431 | AE49: 1296708
B51: Weighted average number of outstanding shares – Diluted (in thousands of shares) | C51: 4808200 | D51: 4676977 | E51: 4671761 | F51: 4665688.4 | G51: 4660405 | H51: 1602126 | I51: 1379271 | J51: 1357132 | K51: 1347258 | L51: 1315578 | M51: 1309861 | N51: 1304431 | O51: 1296708 | R51: Número médio ponderado de ações em circulação - diluída (em milhares de ações) | S51: 4808200 | T51: 4676977 | U51: 4671761 | V51: 4665688.4 | W51: 4660405 | X51: 1602126 | Y51: 1379271 | Z51: 1357132 | AA51: 1347258 | AB51: 1315578 | AC51: 1309861 | AD51: 1304431 | AE51: 1296708

Sheet Financial Position (Balanços Pa
B2: Nu Holdings Ltd. | P2: Nu Holdings Ltd.
B3: Consolidated Statement of Financial Position | P3: Balanços Patrimoniais Consolidados
B4: Amounts in thousands of US$ | P4: Valores em R$ mil
B5: Back to Contents | P5: Retornar ao Índice
C10: 31/3/2023 | D10: 44926 | E10: 44834 | F10: 44742 | G10: 44651 | H10: 44561 | I10: 44469 | J10: 44377 | K10: 44286 | L10: 44196 | M10: 43830 | Q10: 31/3/2023 | R10: 44926 | S10: 44834 | T10: 44742 | U10: 44651 | V10: 44561 | W10: 44469 | X10: 44377 | Y10: 44286 | Z10: 44196 | AA10: 43830
C11: US$ | D11: US$ | E11: US$ | F11: US$ | G11: US$ | H11: US$ | I11: US$ | J11: US$ | K11: US$ | L11: US$ | M11: US$ | Q11: R$ | R11: R$ | S11: R$ | T11: R$ | U11: R$ | V11: R$ | W11: R$ | X11: R$ | Y11: R$ | Z11: R$ | AA11: R$
B12: Assets | P12: Ativo
B13: Cash and cash equivalents | C13: 4310496 | D13: 4172316 | E13: 3692793 | F13: 3701020 | G13: 2968622 | H13: 2705675 | I13: 1996725 | J13: 2662467 | K13: 2200663 | L13: 2343780 | M13: 1246566 | P13: Caixa e equivalentes de caixa | Q13: 21824472 | R13: 22031497 | S13: 19998320 | T13: 19455522 | U13: 14076315 | V13: 15086303 | W13: 10867975 | X13: 13231396 | Y13: 12397875 | Z13: 12184140 | AA13: 5024160
B14: Financial assets at fair value through profit or loss | C14: 109033 | D14: 133643 | E14: 780827 | F14: 967329 | G14: 1037055 | H14: 918332 | I14: 4780936 | J14: 5390216 | K14: 4405577 | L14: 4378118 | M14: 2400691 | P14: Ativos financeiros ao valor justo por meio do resultado | Q14: 552045 | R14: 705689 | S14: 4228569 | T14: 5085055 | U14: 4917403 | V14: 5120436 | W14: 26022157 | X14: 26787217 | Y14: 24819700 | Z14: 22759646 | AA14: 9675744
B15: Securities | C15: 94038 | D15: 91853 | E15: 740972 | F15: 856994 | G15: 817443 | H15: 815962 | I15: 4680014 | J15: 5343289 | K15: 4356451 | L15: 4287277 | M15: 2237673 | P15: Títulos e valores mobiliários | Q15: 476124 | R15: 485021 | S15: 4012734 | T15: 4505046 | U15: 3876069 | V15: 4549641 | W15: 25472848 | X15: 26554009 | Y15: 24542938 | Z15: 22287409 | AA15: 9018717
B16: Derivative financial instruments | C16: 14686 | D16: 41485 | E16: 39552 | F16: 109934 | G16: 209439 | H16: 101318 | I16: 89543 | J16: 5845 | K16: 34 | L16: 80 | M16: 241 | P16: Instrumentos financeiros derivativos | Q16: 74357 | R16: 219057 | S16: 214194 | T16: 577901 | U16: 993097 | V16: 564929 | W16: 487374 | X16: 29047 | Y16: 192 | Z16: 416 | AA16: 971
B17: Collateral for credit card operations | C17: 309 | D17: 305 | E17: 303 | F17: 401 | G17: 10173 | H17: 1052 | I17: 11379 | J17: 41082 | K17: 49092 | L17: 90761 | M17: 162777 | P17: Garantias para operações de cartão de crédito | Q17: 1564 | R17: 1611 | S17: 1641 | T17: 2108 | U17: 48237 | V17: 5866 | W17: 61935 | X17: 204161 | Y17: 276570 | Z17: 471821 | AA17: 656056
B18: Financial assets at fair value through other comprehensive income | C18: 7916143 | D18: 9947138 | E18: 8931961 | F18: 8850741 | G18: 9260432 | H18: 8163428 | I18: 1837715 | J18: 348518 | K18: 0 | L18: 0 | M18: 0 | P18: Ativos financeiros a valor justo através de outros resultados abrangentes | Q18: 40080224 | R18: 52524867 | S18: 48371035 | T18: 46526575 | U18: 43910190 | V18: 45517642 | W18: 10002499 | X18: 1731995 | Y18: 0 | Z18: 0 | AA18: 0
B19: Securities | C19: 7916143 | D19: 9947138 | E19: 8931961 | F19: 8850741 | G19: 9260432 | H19: 8163428 | I19: 1837715 | J19: 348518 | K19: 0 | L19: 0 | M19: 0 | P19: Títulos e valores mobiliários | Q19: 40080224 | R19: 52524867 | S19: 48371035 | T19: 46526575 | U19: 43910190 | V19: 45517642 | W19: 10002499 | X19: 1731995 | Y19: 0 | Z19: 0 | AA19: 0
B20: Financial assets at amortized cost | C20: 15029584 | D20: 13684484 | E20: 10908864 | F20: 10141709 | G20: 9571139 | H20: 6982835 | I20: 5335867 | J20: 4634392 | K20: 3172369 | L20: 3150013 | M20: 2923676 | P20: Ativos financeiros ao custo amortizado | Q20: 76096287 | R20: 72259550 | S20: 59076952 | T20: 53312935 | U20: 45383469 | V20: 38934892 | W20: 29042591 | X20: 23031075 | Y20: 17872172 | Z20: 16375342 | AA20: 11783585
B21: Credit card receivables | C21: 9158452 | D21: 8233072 | E21: 6987948 | F21: 6478470 | G21: 6234824 | H21: 4780520 | I21: 4061505 | J21: 3819891 | K21: 2787813 | L21: 2908907 | M21: 2786524 | P21: Recebíveis de cartões de crédito | Q21: 46370158 | R21: 43473913 | S21: 37843232 | T21: 34056021 | U21: 29563665 | V21: 26655223 | W21: 22106366 | X21: 18983330 | Y21: 15705700 | Z21: 15121953 | AA21: 11230808
B22: Loans to customers | C22: 2020191 | D22: 1673440 | E22: 1603105 | F22: 1675776 | G22: 1667517 | H22: 1194814 | I22: 792736 | J22: 519686 | K22: 264542 | L22: 174694 | M22: 58024 | P22: Empréstimos para clientes | Q22: 10228922 | R22: 8836433 | S22: 8681615 | T22: 8809219 | U22: 7906865 | V22: 6662044 | W22: 4314783 | X22: 2582632 | Y22: 1490350 | Z22: 908146 | AA22: 233860
B23: Compulsory and other deposits at central banks | C23: 2671668 | D23: 2778019 | E23: 1860438 | F23: 1552139 | G23: 1333427 | H23: 938659 | I23: 422649 | J23: 265465 | K23: 98694 | L23: 43542 | M23: 0 | P23: Depósitos compulsórios e outros em bancos centrais | Q23: 13526922 | R23: 14669052 | S23: 10075202 | T23: 8159284 | U23: 6322711 | V23: 5233775 | W23: 2300436 | X23: 1319255 | Y23: 556012 | Z23: 226353 | AA23: 0
B24: Interbank transactions | C24: - | D24: 0 | E24: 0 | F24: 0 | G24: 0 | H24: 0 | I24: 19749 | J24: 4451 | K24: 1424 | L24: 0 | M24: 91 | P24: Transações interbancárias | Q24: - | R24: 0 | S24: 0 | T24: 0 | U24: 0 | V24: 0 | W24: 107492 | X24: 22120 | Y24: 8022 | Z24: 0 | AA24: 367
B25: Other receivables | C25: 1076681 | D25: 521670 | E25: 381782 | F25: 374188 | G25: 285632 | H25: 50349 | P25: Outros recebíveis | Q25: 5451344 | R25: 2754626 | S25: 2067540 | T25: 1967031 | U25: 1354380 | V25: 280737
B26: Other financial assets | C26: 102592 | D26: 478283 | E26: 75591 | F26: 61136 | G26: 49739 | H26: 18493 | I26: 39228 | J26: 24899 | K26: 19896 | L26: 22870 | M26: 79037 | P26: Outros ativos financeiros ao custo amortizado | Q26: 519434 | R26: 2525526 | S26: 409363 | T26: 321380 | U26: 235848 | V26: 103113 | W26: 213514 | X26: 123738 | Y26: 112088 | Z26: 118890 | AA26: 318550
B27: Other assets | C27: 500225 | D27: 541903 | E27: 388604 | F27: 331383 | G27: 288115 | H27: 232915 | I27: 171170 | J27: 176253 | K27: 133004 | L27: 123495 | M27: 67931 | P27: Outros ativos | Q27: 2532689 | R27: 2861465 | S27: 2104485 | T27: 1742014 | U27: 1366155 | V27: 1298686 | W27: 931661 | X27: 875907 | Y27: 749305 | Z27: 641990 | AA27: 273790
B28: Deferred tax assets | C28: 964179 | D28: 811050 | E28: 700706 | F28: 598917 | G28: 565310 | H28: 360752 | I28: 328458 | J28: 266890 | K28: 178552 | L28: 125131 | M28: 94198 | P28: Ativos fiscais diferidos | Q28: 4881735 | R28: 4282668 | S28: 3794673 | T28: 3148387 | U28: 2680530 | V28: 2011481 | W28: 1787764 | X28: 1326337 | Y28: 1005908 | Z28: 650494 | AA28: 379656
B29: Right-of-use assets | C29: 16811 | D29: 18982 | E29: 17301 | F29: 21888 | G29: 18994 | H29: 6426 | I29: 7454 | J29: 9142 | K29: 8977 | L29: 10660 | M29: 17195 | P29: Ativos de direito de uso | Q29: 85116 | R29: 100233 | S29: 93694 | T29: 115061 | U29: 90064 | V29: 35830 | W29: 40571 | X29: 45432 | Y29: 50574 | Z29: 55416 | AA29: 69303
B30: Property, plant and equipment | C30: 30131 | D30: 27482 | E30: 20609 | F30: 18658 | G30: 18200 | H30: 14109 | I30: 12106 | J30: 12690 | K30: 8952 | L30: 9850 | M30: 8667 | P30: Imobilizado | Q30: 152556 | R30: 145116 | S30: 111608 | T30: 98081 | U30: 86299 | V30: 78669 | W30: 65892 | X30: 63064 | Y30: 50433 | Z30: 51205 | AA30: 34931
B31: Intangible assets | C31: 215303 | D31: 182164 | E31: 167989 | F31: 147432 | G31: 120563 | H31: 72337 | I31: 61847 | J31: 59240 | K31: 12162 | L31: 12372 | M31: 1110 | P31: Ativo intangível | Q31: 1090101 | R31: 961899 | S31: 909744 | T31: 775021 | U31: 571674 | V31: 403337 | W31: 336627 | X31: 306037 | Y31: 68517 | Z31: 64316 | AA31: 4474
B32: Goodwill | C32: 397486 | D32: 397397 | E32: 397334 | F32: 409604 | G32: 409573 | H32: 401872 | I32: 393820 | J32: 391706 | K32: 831 | L32: 831 | M32: - | P32: Ágio | Q32: 2084104 | R32: 2083644 | S32: 2083315 | T32: 2147461 | U32: 2147379 | V32: 2102736 | W32: 2058834 | X32: 2047783 | Y32: 4682 | Z32: 4320 | AA32: -
B33: Total assets | C33: 29489391 | D33: 29916559 | E33: 26006988 | F33: 25188681 | G33: 24258003 | H33: 19858681 | I33: 14926098 | J33: 13951514 | K33: 10121087 | L33: 10154250 | M33: 6760034 | P33: Total do ativo | Q33: 149379104 | R33: 157956628 | S33: 140772395 | T33: 132406112 | U33: 115229478 | V33: 110590012 | W33: 81156571 | X33: 69446243 | Y33: 57019166 | Z33: 52786869 | AA33: 27245643
B35: Liabilities | P35: Passivo
B36: Financial liabilities at fair value through profit or loss | C36: 157435 | D36: 218174 | E36: 69211 | F36: 121978 | G36: 200505 | H36: 102380 | I36: 99169 | J36: 14884 | K36: 110787 | L36: 90796 | M36: 24125 | P36: Passivos financeiros ao valo justo por meio do resultado | Q36: 797109 | R36: 1152047 | S36: 374813 | T36: 641214 | U36: 950734 | V36: 570851 | W36: 539767 | X36: 73967 | Y36: 624140 | Z36: 472003 | AA36: 97233
B37: Derivative financial instruments | C37: 10344 | D37: 9425 | E37: 4048 | F37: 86511 | G37: 177079 | H37: 87278 | I37: 86638 | J37: 122 | K37: 62216 | L37: 75304 | M37: 2041 | P37: Instrumentos financeiros derivativos | Q37: 52373 | R37: 49768 | S37: 21922 | T37: 454771 | U37: 839655 | V37: 486645 | W37: 471562 | X37: 606 | Y37: 350506 | Z37: 391468 | AA37: 8226
B38: Instruments eligible as capital | C38: 2932 | D38: 11507 | E38: 19099 | F38: 18554 | G38: 20226 | H38: 12056 | I38: 12531 | J38: 14762 | K38: 13063 | L38: 15492 | M38: 22084 | P38: Instrumentos elegíveis a capital | Q38: 14845 | R38: 60762 | S38: 103431 | T38: 97535 | U38: 95906 | V38: 67222 | W38: 68205 | X38: 73361 | Y38: 73593 | Z38: 80535 | AA38: 89007
B39: Repurchase agreements | C39: 144159 | D39: 197242 | E39: 46064 | F39: 16913 | G39: 3200 | H39: 3046 | I39: 0 | J39: - | K39: 35508 | P39: Compromisso de recompra | Q39: 729891 | R39: 1041517 | S39: 249460 | T39: 88908 | U39: 15173 | V39: 16984 | W39: 0 | X39: - | Y39: 200041 | Z39: 0 | AA39: 0
B40: Financial liabilities at amortized cost | C40: 23280670 | D40: 23448892 | E40: 20402552 | F40: 19695082 | G40: 18665367 | H40: 14706713 | I40: 12378683 | J40: 11602615 | K40: 8947550 | L40: 9421710 | M40: 5972989 | P40: Passivos financeiros ao custo amortizado | Q40: =SUM(Q41:Q43) -> 117872361 | R40: 123819529 | S40: 110490020 | T40: 103533107 | U40: 88505571 | V40: 82001690 | W40: 67375934 | X40: 57660355 | Y40: 50407813 | Z40: 48978760 | AA40: 24073535
B41: Deposits | C41: 15757663 | D41: 15808541 | E41: 14040157 | F41: 13293235 | G41: 12596927 | H41: 9667300 | I41: 8089835 | J41: 7505684 | K41: 5461652 | L41: 5584862 | M41: 2693158 | P41: Depósitos | Q41: 79782624 | R41: 83475420 | S41: 76034470 | T41: 69879878 | U41: 59730849 | V41: 53902931 | W41: 44032163 | X41: 37300247 | Y41: 30769309 | Z41: 29032905 | AA41: 10854504
B42: Payables to network | C42: 6871826 | D42: 7054783 | E42: 5894436 | F42: 5930966 | G42: 5920795 | H42: 4882159 | I42: 4127691 | J42: 3990411 | K42: 2982547 | L42: 3331258 | M42: 2976505 | P42: Valores a repassar à rede | Q42: 34792742 | R42: 37252076 | S42: 31921318 | T42: 31177902 | U42: 28074634 | V42: 27221942 | W42: 22466609 | X42: 19830747 | Y42: 16802775 | Z42: 17317545 | AA42: 11996506
B43: Borrowings and financing | C43: 651181 | D43: 585568 | E43: 467959 | F43: 470881 | G43: 147645 | H43: 147243 | I43: 134398 | J43: 59165 | K43: 103220 | L43: 97454 | M43: 133401 | P43: Empréstimos e financiamentos | Q43: 3296995 | R43: 3092033 | S43: 2534232 | T43: 2475327 | U43: 700088 | V43: 820998 | W43: 731515 | X43: 294026 | Y43: 581511 | Z43: 506615 | AA43: 537659
B44: Securitized borrowings | C44: - | D44: - | E44: - | F44: 0 | G44: 0 | H44: 10011 | I44: 26759 | J44: 47355 | K44: 57681 | L44: 79742 | M44: 169925 | P44: Empréstimos securitizados | Q44: - | R44: - | S44: - | T44: 0 | U44: 0 | V44: 55819 | W44: 145647 | X44: 235335 | Y44: 324957 | Z44: 414539 | AA44: 684866
B45: Senior preferred shares | C45: - | D45: 0 | E45: 0 | F45: - | G45: - | H45: - | I45: - | J45: - | K45: 342450 | L45: 328394 | M45: 0 | P45: Ações preferenciais seniores | Q45: - | R45: 0 | S45: 0 | T45: 0 | U45: 0 | V45: - | W45: - | X45: - | Y45: 1929261 | Z45: 1707156 | AA45: -
B46: Salaries, allowances and social security contributions | C46: 101288 | D46: 90587 | E46: 107547 | F46: 88070 | G46: 115599 | H46: 97909 | I46: 68506 | J46: 53995 | K46: 35740 | L46: 25848 | M46: 11238 | P46: Salários, abonos e encargos sociais | Q46: 512831 | R46: 478336 | S46: 582421 | T46: 462966 | U46: 548136 | V46: 545921 | W46: 372871 | X46: 268334 | Y46: 201348 | Z46: 134371 | AA46: 45294
...

Sheet Cash Flow (fluxo de caixa)
B2: Nu Holdings Ltd. | R2: Nu Holdings Ltd.
B3: Consolidated Statement of Cash Flow | R3: Demonstrações Consolidadas do Fluxo de Caixa
B4: Amounts in thousands of US$ | R4: Valores em R$ mil
B5: Back to Contents | R5: Retornar ao Índice
C10: 31/3/2023 | D10: 44926 | E10: 44834 | F10: 44742 | G10: 44651 | H10: 44561 | I10: 44469 | J10: 44377 | K10: 44286 | L10: 44196 | M10: 44104 | N10: 44012 | O10: 43921 | P10: 43830 | S10: 31/3/2023 | T10: 44926 | U10: 44834 | V10: 44742 | W10: 44651 | X10: 44561 | Y10: 44469 | Z10: 44377 | AA10: 44286 | AB10: 44196 | AC10: 44104 | AD10: 44012 | AE10: 43921 | AF10: 43830
C11: US$ | D11: US$ | E11: US$ | F11: US$ | G11: US$ | H11: US$ | I11: US$ | J11: US$ | K11: US$ | L11: US$ | M11: US$ | N11: US$ | O11: US$ | P11: US$ | S11: R$ | T11: R$ | U11: R$ | V11: R$ | W11: R$ | X11: R$ | Y11: R$ | Z11: R$ | AA11: R$ | AB11: R$ | AC11: R$ | AD11: R$ | AE11: R$ | AF11: R$
B12: Cash flows from operating activities | R12: Fluxos de caixa das atividades operacionais
B13: Reconciliation of profit (loss) to net cash flows from operating activities: | R13: Reconciliação do lucro (prejuízo) com os fluxos de caixa líquidos das atividades operacionais:
B14: Profit (Loss) for the period/year | C14: 141751 | D14: -364634 | E14: -67021 | F14: -74854 | G14: -45004 | H14: -165334 | I14: -99060 | J14: -64703 | K14: -49483 | L14: -171491 | M14: -64434 | N14: -31872 | O14: -33433 | P14: -92531 | R14: Lucro (Prejuízo) do período/exercício | S14: 736027 | T14: -1883444 | U14: -344133 | V14: -379965 | W14: -235146 | X14: -892192 | Y14: -528356 | Z14: -348535 | AA14: -271443 | AB14: -885408 | AC14: -327647 | AD14: -156981 | AE14: -149530 | AF14: -364960
B15: Adjustments: | R15: Ajustes:
B16: Depreciation and amortization | C16: 13179 | D16: 35581 | E16: 25699 | F16: 18088 | G16: 7655 | H16: 17339 | I16: 10896 | J16: 5242 | K16: 2507 | L16: 7428 | M16: 3783 | N16: 2893 | O16: 560 | P16: 5073 | R16: Depreciação e amortização | S16: 68431 | T16: 183785 | U16: 131957 | V16: 91816 | W16: 39997 | X16: 93566 | Y16: 58116 | Z16: 28237 | AA16: 13752 | AB16: 38351 | AC16: 19237 | AD16: 14249 | AE16: 2505 | AF16: 20009
B17: Credit loss allowance expenses | C17: 491937 | D17: 1440922 | E17: 1009827 | F17: 625185 | G17: 279489 | H17: 503679 | I17: 299404 | J17: 165815 | K17: 77210 | L17: 187790 | M17: 126184 | N17: 87430 | O17: 64181 | P17: 193967 | R17: Despesas com provisão para perdas de crédito | S17: 2554334 | T17: 7442795 | U17: 5185159 | V17: 3173502 | W17: 1460330 | X17: 2718002 | Y17: 1596931 | Z17: 893196 | AA17: 423543 | AB17: 969560 | AC17: 641646 | AD17: 430627 | AE17: 287050 | AF17: 765045
B18: Deferred income taxes | C18: -103986 | D18: -417612 | E18: -322255 | F18: -212710 | G18: -121699 | H18: -224654 | I18: -132732 | J18: -78958 | K18: -35392 | L18: -44025 | M18: -24079 | N18: -18613 | O18: -19404 | P18: -40340 | R18: Tributos diferidos | S18: -539937 | T18: -2157091 | U18: -1654683 | V18: -1079737 | W18: -635877 | X18: -1212300 | Y18: -707953 | Z18: -425323 | AA18: -194147 | AB18: -227301 | AC18: -122442 | AD18: -91676 | AE18: -86785 | AF18: -159109
B19: Customer program | C19: - | D19: - | E19: 0 | F19: 0 | G19: 0 | H19: 11180 | I19: 0 | J19: 0 | K19: 0 | L19: 0 | M19: 0 | N19: 0 | O19: 0 | P19: 0 | R19: Programa de clientes | S19: - | T19: - | U19: 0 | V19: 0 | W19: 0 | X19: 60331 | Y19: 0 | Z19: 0 | AA19: 0 | AB19: 0 | AC19: 0 | AD19: 0 | AE19: 0 | AF19: 0
B20: Provision for lawsuits and administrative proceedings | C20: 1239 | D20: -1174 | E20: -1382 | F20: -1958 | G20: -2147 | H20: 2818 | I20: 502 | J20: 320 | K20: 338 | L20: 227 | M20: 338 | N20: 154 | O20: 131 | P20: 7386 | R20: Provisão para processos judiciais e administrativos | S20: 6433 | T20: -6062 | U20: -7096 | V20: -9938 | W20: -11218 | X20: 15207 | Y20: 2678 | Z20: 1724 | AA20: 1854 | AB20: 1171 | AC20: 1719 | AD20: 759 | AE20: 585 | AF20: 29134
B21: Unrealized losses (gains) on other investments | C21: 18298 | D21: 848 | E21: -5067 | F21: -5067 | G21: -14055 | H21: -39280 | I21: 0 | J21: 0 | K21: 0 | L21: 0 | M21: 0 | N21: 0 | O21: 0 | P21: 0 | R21: Ganhos (perdas) sobre outros investimentos | S21: 95011 | T21: 4380 | U21: -26018 | V21: -25721 | W21: -50166 | X21: -219018 | Y21: 0 | Z21: 0 | AA21: 0 | AB21: 0 | AC21: 0 | AD21: 0 | AE21: 0 | AF21: 0
B22: Unrealized losses (gains) on financial instruments | C22: 4437 | D22: 17794 | E22: 14063 | F22: 38458 | G22: 13508 | H22: 19338 | I22: 161370 | J22: 95216 | K22: 87090 | L22: 48433 | M22: 13067 | N22: -18584 | O22: -6524 | P22: 1799 | R22: Ganhos (perdas) sobre instrumentos financeiros | S22: 23039 | T22: 91911 | U22: 72209 | V22: 195217 | W22: 70579 | X22: 104354 | Y22: 860699 | Z22: 512900 | AA22: 477741 | AB22: 250060 | AC22: 66446 | AD22: -91533 | AE22: -29178 | AF22: 7096
B23: Interest accrued | C23: 16463 | D23: 32479 | E23: 21877 | F23: 8907 | G23: 3706 | H23: 11077 | I23: 7186 | J23: 4658 | K23: 16946 | L23: 39521 | M23: 22770 | N23: 7185 | O23: 4353 | P23: 17681 | R23: Juros incorridos | S23: 85482 | T23: 167764 | U23: 112332 | V23: 45213 | W23: 19364 | X23: 59775 | Y23: 38328 | Z23: 25091 | AA23: 92960 | AB23: 204045 | AC23: 115785 | AD23: 35388 | AE23: 19469 | AF23: 69737
B24: Share-based payments - Contingency share award (CSA) - termination | C24: - | D24: 355573 | E24: 0 | F24: 0 | G24: 0 | H24: 0 | I24: 0 | J24: 0 | K24: 0 | L24: 0 | M24: 0 | N24: 0 | O24: 0 | P24: 0 | R24: Pagamento baseado em ações - rescisão do prêmio de ação contingente | S24: - | T24: 1836641 | U24: 0 | V24: 0 | W24: 0 | X24: 0 | Y24: 0 | Z24: 0 | AA24: 0 | AB24: 0 | AC24: 0 | AD24: 0 | AE24: 0 | AF24: 0
B25: Share-based payments granted | C25: 57857 | D25: 253203 | E25: 188525 | F25: 135656 | G25: 42100 | H25: 152717 | I25: 79729 | J25: 53512 | K25: 32200 | L25: 35569 | M25: 20157 | N25: 14053 | O25: 7111 | P25: 18511 | R25: Pagamento baseado em ações concedido | S25: 300417 | T25: 1307869 | U25: 968019 | V25: 688606 | W25: 219973 | X25: 848968 | Y25: 401521 | Z25: 288258 | AA25: 176637 | AB25: 183643 | AC25: 102498 | AD25: 69216 | AE25: 31804 | AF25: 73011
B26: Others | C26: - | D26: 8203 | E26: 5879 | F26: 0 | G26: 0 | H26: 0 | I26: 0 | J26: 0 | K26: 0 | L26: 0 | M26: 0 | N26: 0 | O26: 0 | P26: 0 | R26: Outros | S26: - | T26: 42371 | U26: 30182 | V26: 0 | W26: 0 | X26: 0 | Y26: 0 | Z26: 0 | AA26: 0 | AB26: 0 | AC26: 0 | AD26: 0 | AE26: 0 | AF26: 0
C27: 641175 | D27: =SUM(D14:D26) -> 1361183 | E27: 870145 | F27: 531705 | G27: 163553 | H27: 288880 | I27: 327295 | J27: 181102 | K27: 131416 | L27: 103452 | M27: 97786 | N27: 42646 | O27: 16975 | P27: 111546 | S27: 3329237 | T27: =SUM(T14:T26) -> 7030919 | U27: 4467928 | V27: 2698993 | W27: 877836 | X27: 1576693 | Y27: 1721964 | Z27: 975548 | AA27: 720897 | AB27: 534121 | AC27: 497242 | AD27: 210049 | AE27: 75920 | AF27: 439963
B28: Changes in operating assets and liabilities: | R28: Variação de ativos e passivos operacionais:
B29: Securities | C29: 1968358 | D29: -1102864 | E29: -749991 | F29: -773539 | G29: -991777 | H29: -4666792 | I29: -2279875 | J29: -1238495 | K29: -1089592 | L29: -2008861 | M29: -865895 | N29: -178688 | O29: 102672 | P29: -1689547 | R29: Títulos e valores mobiliários | S29: 10220502 | T29: -5696623 | U29: -3850979 | V29: -3926561 | W29: -5182035 | X29: -25183410 | Y29: -12160169 | Z29: -6671400 | AA29: -5977068 | AB29: -10371747 | AC29: -4403076 | AD29: -880108 | AE29: 459200 | AF29: -6663911
B30: Compulsory deposits and others at central banks | C30: 5422915 | D30: -1880347 | E30: -972188 | F30: -635319 | G30: -358253 | H30: -924889 | I30: -386869 | J30: -204739 | K30: -65951 | L30: -43841 | M30: - | N30: 0 | O30: - | P30: - | R30: Depósitos compulsórios em bancos centrais | S30: 28157944 | T30: -9712556 | U30: -4991894 | V30: -3224943 | W30: -1871872 | X30: -4990979 | Y30: -2063443 | Z30: -1102869 | AA30: -361779 | AB30: -226353 | AC30: - | AD30: 0 | AE30: - | AF30: -
B31: Credit card receivables | C31: -7973331 | D31: -5213669 | E31: -3502428 | F31: -2459157 | G31: -1576633 | H31: -2568423 | I31: -1594432 | J31: -1066399 | K31: -608551 | L31: -470227 | M31: 652567 | N31: 366816 | O31: 345824 | P31: -1414489 | R31: Recebíveis de cartão de crédito | S31: -41400724 | T31: -26930164 | U31: -17983917 | V31: -12482927 | W31: -8237907 | X31: -13859981 | Y31: -8504222 | Z31: -5744371 | AA31: -3338260 | AB31: -2427774 | AC31: 3318304 | AD31: 1806712 | AE31: 1546697 | AF31: -5579028
B32: Loans to customers | C32: 374403 | D32: -1889278 | E32: -1548747 | F32: -1145997 | G32: -673860 | H32: -1522217 | I32: -875629 | J32: -426329 | K32: -175395 | L32: -178686 | M32: -27279 | N32: -18514 | O32: -24499 | P32: -63009 | R32: Empréstimos para clientes | S32: 1944050 | T32: -9758688 | U32: -7952351 | V32: -5817195 | W32: -3520919 | X32: -8214340 | Y32: -4670343 | Z32: -2296507 | AA32: -962147 | AB32: -922558 | AC32: -138713 | AD32: -91189 | AE32: -109572 | AF32: -248520
B33: Other credit operations | C33: -541190 | D33: -481824 | E33: -349558 | F33: -335367 | G33: 0 | H33: 0 | I33: 0 | J33: 0 | K33: 0 | L33: 0 | M33: 0 | N33: 0 | O33: 0 | P33: 0 | R33: Outras operações de crédito | S33: -2810075 | T33: -2488766 | U33: -1794875 | V33: -1702356 | W33: 0 | X33: 0 | Y33: 0 | Z33: 0 | AA33: 0 | AB33: 0 | AC33: 0 | AD33: 0 | AE33: 0 | AF33: 0
B34: Interbank transactions | C34: - | D34: 0 | E34: - | F34: 0 | G34: 0 | H34: - | I34: -20153 | J34: -4106 | K34: -1462 | L34: 93 | M34: -5008 | N34: -3142 | O34: 93 | P34: -91 | R34: Transações interbancárias | S34: - | T34: 0 | U34: - | V34: 0 | W34: 0 | X34: 0 | Y34: -107490 | Z34: -22120 | AA34: -8022 | AB34: 480 | AC34: -25466 | AD34: -15476 | AE34: 416 | AF34: -359
B35: Other assets | C35: 406972 | D35: -772415 | E35: -210427 | F35: -145172 | G35: -299995 | H35: -64072 | I35: 19379 | J35: -1353 | K35: -14617 | L35: 78319 | M35: 77888 | N35: 84742 | O35: -17671 | P35: -166173 | R35: Outros ativos | S35: 2113161 | T35: -3989755 | U35: -1080480 | V35: -736908 | W35: -1567474 | X35: -345752 | Y35: 103362 | Z35: -7290 | AA35: -80182 | AB35: 404362 | AC35: 396060 | AD35: 417387 | AE35: -79035 | AF35: -655422
B36: Deposits | C36: -49611 | D36: 6278088 | E36: 4611994 | F36: 3755012 | G36: 2658644 | H36: 4001856 | I36: 2343522 | J36: 1579763 | K36: 1067551 | L36: 2871246 | M36: 1529163 | N36: 773253 | O36: 12212 | P36: 2088793 | R36: Depósitos | S36: -257600 | T36: 32428208 | U36: 23681206 | V36: 19060816 | W36: 13891415 | X36: 21595216 | Y36: 12499643 | Z36: 8509709 | AA36: 5856160 | AB36: 14824243 | AC36: 7775794 | AD36: 3808572 | AE36: 54619 | AF36: 8238617
B37: Payables to network | C37: -178401 | D37: 2221037 | E37: 1067635 | F37: 1086143 | G37: 942565 | H37: 1602485 | I37: 812739 | J37: 608114 | K37: 354124 | L37: 312607 | M37: -510635 | N37: -601255 | O37: -485189 | P37: 1365476 | R37: Valores a repassar à rede | S37: -926329 | T37: 11472322 | U37: 5481985 | V37: 5513370 | W37: 4924902 | X37: 8647490 | Y37: 4334906 | Z37: 3275727 | AA37: 1942582 | AB37: 1613990 | AC37: -2596579 | AD37: -2961415 | AE37: -2170006 | AF37: 5385710
B38: Deferred income | C38: 5299 | D38: 11277 | E38: 6110 | F38: 6149 | G38: 5884 | H38: 4848 | I38: 3525 | J38: 5216 | K38: 5869 | L38: 3621 | M38: -3095 | N38: 1690 | O38: 63 | P38: 10325 | R38: Receita diferida | S38: 27515 | T38: 58249 | U38: 31373 | V38: 31213 | W38: 30744 | X38: 26161 | Y38: 18801 | Z38: 28098 | AA38: 32194 | AB38: 18695 | AC38: -15738 | AD38: 8324 | AE38: 281 | AF38: 40724
B39: Other liabilities | C39: -134691 | D39: 979277 | E39: 423586 | F39: 230430 | G39: 144112 | H39: 417225 | I39: 278819 | J39: 128811 | K39: 111629 | L39: 57841 | M39: 32278 | N39: -1997 | O39: 364 | P39: 52366 | R39: Outros passivos | S39: -699370 | T39: 5058259 | U39: 2174987 | V39: 1169686 | W39: 752985 | X39: 2251471 | Y39: 1487137 | Z39: 693865 | AA39: 612350 | AB39: 298633 | AC39: 164133 | AD39: -9836 | AE39: 1626 | AF39: 206543
